Workbook
Name CV_AIConfidence: 'Controlled Values'!$A$5:$A$7
Name CV_CandidateAssessment: 'Controlled Values'!$F$5:$F$7
Name CV_ClusterAssignmentType: 'Controlled Values'!$P$5:$P$8
Name CV_ClusterStatus: 'Controlled Values'!$I$5:$I$7
Name CV_EntityType: 'Controlled Values'!$M$5:$M$14
Name CV_EvidenceRecordType: 'Controlled Values'!$O$5:$O$6
Name CV_ExceptionSeverity: 'Controlled Values'!$J$5:$J$8
Name CV_InitiativeMappingRelationship: 'Controlled Values'!$E$5:$E$10
Name CV_InitiativeStatus: 'Controlled Values'!$H$5:$H$11
Name CV_PracticeMappingRelationship: 'Controlled Values'!$D$5:$D$9
Name CV_ProblemMappingRelationship: 'Controlled Values'!$C$5:$C$10
Name CV_RecordOrigin: 'Controlled Values'!$L$5:$L$6
Name CV_ResolutionStatus: 'Controlled Values'!$K$5:$K$8
Name CV_ReviewDecision: 'Controlled Values'!$N$5:$N$8
Name CV_ReviewStatus: 'Controlled Values'!$B$5:$B$9
Name CV_YesNo: 'Controlled Values'!$G$5:$G$6

Sheet Read Me
A1: Controlled Consolidation Working Workbook
A2: Step 0 structure for controlled consolidation; source workbooks are not modified.
A4: WORKFLOW AND REVIEW GATES
A5: 1. Import | B5: Copy every source column unchanged into Problems and Practices; add controlled metadata to the right.
A6: 2. Assess | B6: Generate candidate problems only in a later approved step, with evidence and confidence rationale.
A7: 3. Map | B7: Review candidate-to-problem, practice-to-problem, and initiative-to-problem relationships.
A8: 4. Cluster | B8: Define clusters separately from overlapping, many-to-many evidence-record assignments.
A9: 5. Review | B9: A reviewer explicitly records governing decisions in Review Log; records are not automatically approved.
A10: Imported confidence | B10: Imported Problems and Practices have blank AIConfidence and ConfidenceReason.
A11: ReviewDecisionID | B11: When retained in an entity table, this identifies the current governing review decision.
A13: CONTROL PRINCIPLES
A14: Entity IDs | B14: Imported problems use WS1-P###; practices use ESP-S###; ESP-P### remains the existing derived-problem reference. New IDs are created only for approved new problems and controlled records.
A15: Review gate | B15: Not reviewed and In review records are working records. Approval requires an explicit review decision.
A16: Decision log | B16: ReviewLog is explicitly maintained and is not an automatic audit trail; changes, versions, and timestamps are not captured automatically.
A17: ClusterStatus | B17: Describes whether a cluster definition is Draft, Active, or Retired.
A18: ReviewStatus | B18: Describes the review stage of a record: Not reviewed, In review, Needs clarification, Approved, or Rejected.
A19: Evidence discipline | B19: Owner, sponsoring unit, initiative status, and evidence date remain blank when not explicitly supported by a source.
A20: EVIDENCE RECORDS AND OVERLAPPING CLUSTER ASSIGNMENTS
A21: Evidenced problem space | B21: The evidenced problem space consists of Workshop problems and ESP-derived problem records. | C21: EPS = Existing Practices and Standards
A22: Direct assignment | B22: Both record types may be assigned directly to clusters.
A23: Multiple assignments | B23: A problem may be assigned to several clusters.
A24: Analytical lenses | B24: Clusters are overlapping analytical lenses, not mutually exclusive containers.
A25: Primary assignment | B25: A problem should normally have no more than one Primary assignment.
A26: Permitted types | B26: Secondary, Boundary and Cross-cutting assignments are permitted.
A27: Unique problems | B27: Multiple cluster assignments for one evidence record do not represent additional unique problems.
A28: Cluster counts | B28: Cluster-level problem counts must distinguish unique evidence records from assignment rows.
A29: CONTENTS
A30: Problems | B30: Imported Workshop 1 problems retain Source problem ID (WS1-P###). Approved new problems may be added later with new controlled IDs.
A31: Practices | B31: Imported practices retain Practice ID (ESP-S###) and preserve Derived problem ID (ESP-P###) as the existing ESP reference.
A32: Candidate Problems | B32: One row per proposed problem derived from evidence. Step 0 contains headings only.
A33: Problem Mappings | B33: Relates a candidate problem to an imported or approved problem using the controlled relationship list.
A34: Practice Mappings | B34: Relates an existing practice to a problem using the controlled relationship list.
A35: Initiatives | B35: One row per initiative. Evidence-based owner, unit, status, and date remain blank unless explicitly supported by a source.
A36: Initiative Mappings | B36: Links one initiative to one problem. No mappings are created in Step 0.
A37: Clusters | B37: One row per cluster definition. ClusterStatus describes lifecycle; ReviewStatus describes review progress.
A38: Cluster Assignments | B38: One row per EvidenceRecordID–ClusterID assignment. Workshop problems and ESP-derived problem records may be assigned directly to several overlapping clusters; no assignments have been created.
A39: Exceptions | B39: Records controlled data-quality issues, conflicts, omissions, and approved deviations.
A40: Review Log | B40: Explicitly maintained decision log. It is not an automatic audit trail.
A41: Controlled Values | B41: Controlled validation lists used by the workbook.

Sheet WS2_ProblemClusters
A1: CLUSTERING OF WORKSHOP 1 PROBLEMS
A4: Cluster ID | B4: Cluster Name | C4: Classification | D4: Cluster Description | E4: Sum of cross-unit problem relevance+vote for the Primary Problem Assignments, WS1-08-26 | F4: Avg cross-unit relevance per primary problem (Col H, max 21), WS1 08-26 | G4: Number of existing local practices relevant to primary problem assignments | H4: Sum of cross-unit relevance for the relevant local practices, WS-06-262 | I4: Primary Problem Assignments | J4: Secondary Problem Assignments | K4: Cross-cutting Problem Assignments | L4: Relevant ongoing initiatives 08-26 | M4: Relevant existing local Standards and Practices Q2-26 | N4: Why this is a useful or unsuitable focus area for initiative ideation | O4: Inclusion Rule | P4: Boundary Rule | Q4: Potential overlap or boundary issues requiring human review
A5: C02 | B5: Consistent and reusable project production environments | C5: Investable opportunity space | D5: Problems caused by inconsistent project setups, standards, platforms, configurations, or local working methods that make projects slow to start, difficult to transfer, and hard to reuse across countries or projects. | E5: 116 | F5: 18 | G5: 21 | H5: 336 | I5: WS1-P011 Difficult cross-country project handover; WS1-P012 Local standards hinder work sharing; WS1-P014 Confusion from multiple project platforms; WS1-P016 Misaligned setups across software vendors; WS1-P017 Fragmented project setup and infrastructure; WS1-P018 Project standards not fully implemented | J5: WS1-P006 Inconsistent data setup across tools; WS1-P015 Inefficient file exchange between vendors; WS1-P019 Coordination challenges in multidisciplinary projects | K5: WS1-P027 Consistency accross departments in terms of digital plan and focus, lack of HoD KPI's supporting improvements in the digital space | L5: PI-RTR-001 RTR Software Standardisation Exercise: Transport-wide exercise to map engineering software by service line/spearhead, identify overlaps, improve interoperability and establish an evidence-based basis for possible standardisation and rationalisation. PI-RTR-002 Unified Production Environment: Global initiative to align supported production platforms, interoperability, data governance, production knowledge and streamlined project environments, with AI and data-centric delivery as target outcomes. PI-RTR-003 Transforming Document Management: Global project to redesign document-management processes, implement a fit-for-purpose DMS and drive behavioural change and adoption across Ramboll projects. PI-RTR-006 Software processes & portal: Ramboll Tech workstream improving software-portfolio governance, employee software journeys, request workflows and production-software support flows. PI-RTR-007 Building our Project Management and Delivery department within Major Projects: Transport Major Projects initiative to build geographically distributed PMD capability supporting more reliable and harmonised delivery of large infrastructure projects. | M5: ESP-S001 ProjectWise manager governance model (Denmark); ESP-S002 ProjectWise manager guide and standards portal (Denmark); ESP-S003 ProjectWise for production - RAMDK (Denmark); ESP-S004 Managed workspace in ProjectWise (Denmark); ESP-S005 CAD project manual and transport standards portal (Denmark); ESP-S007 Client-led data management and modelling instruction model (Finland); ESP-S008 Quadri / Trimble Connect project environment (Finland); ESP-S009 Finnish configuration packages for design tools (Finland); ESP-S010 Forma pilot with discipline templates (Finland); ESP-S011 Transport software standards portal and Teams communication channels (Finland); ESP-S012 Super-user network and office roadshow support model (Finland); ESP-S013 Integrated multi-platform project environment (Norway); ESP-S017 Project SharePoint/Teams information hub (Norway); ESP-S019 CAD Configuration / Configuration Switch (Sweden); ESP-S020 Metadata and Naming + Managed Workspaces (Sweden); ESP-S022 Opt-in model via project support SharePoint page (Sweden); ESP-S023 Project Hub (SharePoint coordination layer) (Sweden); ESP-S024 Early-phase digital delivery manager involvement (UK&I); ESP-S025 Digital fit assessment (UK&I); ESP-S026 ISO 19650-aligned ProjectWise deployment model (UK&I); ESP-S027 ProjectWise build sheet and staged mobilisation checks (UK&I) | N5: Strong ideation area. The problems form a coherent conversation about making project delivery more recognisable, repeatable, transferable, and reusable while allowing justified local or project variation. It is broad enough for multiple initiative families but still tied to a clear production outcome. | O5: Include where the main problem is variation in project infrastructure, setup, standards, platform use, or implementation of standard ways of working. | P5: Exclude data naming and semantic consistency where the primary outcome is reusable data rather than repeatable project setup. Exclude general access to guidance unless the principal failure is the setup itself. | Q5: This is the broadest proposed cluster. To break down further can be considered whether project-platform coherence and standards implementation should remain together. C02 must not become a generic "all standards and software" category. WS1-P014 may overlap strongly with C04 because platform confusion can also be an interoperability problem.
A6: C06 | B6: Production knowledge, competence and adoption | C6: Cross-cutting enabler / success factor | D6: Problems where people cannot find, understand, adopt, or consistently apply the knowledge, skills, guidance, and proven working methods needed for effective digital production. | E6: 94 | F6: 16.8 | G6: 10 | H6: 110 | I6: WS1-P013 Scattered guidance and support information; WS1-P020 Limited cross-country innovation sharing; WS1-P023 Underuse of modern modelling features; WS1-P024 Uneven digital-requirements competence; WS1-P026 Delivery teams including REC lack correct skills to deliver digital outputs (models, drawings and data principally) right first time | J6: WS1-P001 Inconsistent use of AI and automation; WS1-P003 Uncoordinated citizen-developed AI tools; WS1-P011 Difficult cross-country project handover; WS1-P012 Local standards hinder work sharing; WS1-P018 Project standards not fully implemented; WS1-P021 No path from prototype to managed product; WS1-P022 Automation difficult to understand and reuse | K6: WS1-P027 Consistency accross departments in terms of digital plan and focus, lack of HoD KPI's supporting improvements in the digital space | L6: PI-RTR-001 RTR Software Standardisation Exercise: Transport-wide exercise to map engineering software by service line/spearhead, identify overlaps, improve interoperability and establish an evidence-based basis for possible standardisation and rationalisation. PI-RTR-002 Unified Production Environment: Global initiative to align supported production platforms, interoperability, data governance, production knowledge and streamlined project environments, with AI and data-centric delivery as target outcomes. PI-RTR-003 Transforming Document Management: Global project to redesign document-management processes, implement a fit-for-purpose DMS and drive behavioural change and adoption across Ramboll projects. PI-RTR-005 Script Sharing Platform rollout and scaling: Scale a live, governed environment for sharing and reusing engineering automation assets including scripts, plugins and visual-programming solutions. PI-RTR-006 Software processes & portal: Ramboll Tech workstream improving software-portfolio governance, employee software journeys, request workflows and production-software support flows. PI-RTR-007 Building our Project Management and Delivery department within Major Projects: Transport Major Projects initiative to build geographically distributed PMD capability supporting more reliable and harmonised delivery of large infrastructure projects. | M6: ESP-S002 ProjectWise manager guide and standards portal (Denmark); ESP-S005 CAD project manual and transport standards portal (Denmark); ESP-S006 Teams-based product information and support channel (Denmark); ESP-S007 Client-led data management and modelling instruction model (Finland); ESP-S011 Transport software standards portal and Teams communication channels (Finland); ESP-S012 Super-user network and office roadshow support model (Finland); ESP-S017 Project SharePoint/Teams information hub (Norway); ESP-S023 Project Hub (SharePoint coordination layer) (Sweden); ESP-S024 Early-phase digital delivery manager involvement (UK&I); ESP-S025 Digital fit assessment (UK&I) | N6: A material supporting enabler and possibly an investable opportunity in its own right. The evidence supports more than generic training: it includes onboarding, access to current guidance, practical application of modern features, cross-country knowledge transfer, and capability to deliver correctly first time. | O6: Include where the main failure is competence, discoverability of guidance, onboarding, learning, adoption, or knowledge transfer. | P6: Exclude standards or project setups where the principal problem persists even when staff know what to do. Exclude tool-product lifecycle and technical integration problems. | Q6: C06 could become too broad if every adoption or competence dependency is assigned here. Human review should preserve the distinction between a root competence problem and competence as one implementation condition for another opportunity. WS1-P020 could alternatively be Primary in C05.
A7: C01 | B7: Reliable project mobilisation and digital delivery governance | C7: Investable opportunity space | D7: Problems where digital requirements, risks, commercial provisions, delivery arrangements, leadership alignment, or multidisciplinary coordination are not established early or consistently enough to support effective project delivery. | E7: 65 | F7: 16 | G7: 8 | H7: 46 | I7: WS1-P008 Digital risks identified too late; WS1-P019 Coordination challenges in multidisciplinary projects; WS1-P025 Current commercial model acts as blocker to digital resources and innovation; WS1-P027 Consistency accross departments in terms of digital plan and focus, lack of HoD KPI's supporting improvements in the digital space | J7: WS1-P017 Fragmented project setup and infrastructure; WS1-P024 Uneven digital-requirements competence | K7: None proposed | L7: PI-RTR-002 Unified Production Environment: Global initiative to align supported production platforms, interoperability, data governance, production knowledge and streamlined project environments, with AI and data-centric delivery as target outcomes. PI-RTR-007 Building our Project Management and Delivery department within Major Projects: Transport Major Projects initiative to build geographically distributed PMD capability supporting more reliable and harmonised delivery of large infrastructure projects. | M7: ESP-S005 CAD project manual and transport standards portal (Denmark); ESP-S013 Integrated multi-platform project environment (Norway); ESP-S014 BIMbot model exchange and automation layer (Norway); ESP-S017 Project SharePoint/Teams information hub (Norway); ESP-S023 Project Hub (SharePoint coordination layer) (Sweden); ESP-S024 Early-phase digital delivery manager involvement (UK&I); ESP-S025 Digital fit assessment (UK&I); ESP-S026 ISO 19650-aligned ProjectWise deployment model (UK&I) | N7: Strong ideation area because it connects early risk identification, coordinated delivery, viable resourcing, and internal alignment. It could support several types of initiative without prescribing the Digital Delivery Manager model or another specific response. Existing digital project roles would not make WS1-P008 non-investable because adoption, timing, coverage, capacity, and effectiveness could still be explored later. | O7: Include where the main production failure occurs during tendering, mobilisation, project planning, establishment of coordinated digital delivery, or internal alignment around digital production improvement. | P7: Exclude problems whose main issue is the technical configuration of tools and environments, data semantics, or the later exchange of information. | Q7: WS1-P019 is sparsely evidenced and might instead sit in C02 if its underlying cause is primarily inconsistent environments and standards. WS1-P025 combines project funding for digital roles with recovery of investment in automation, so its boundary with C07 needs review. WS1-P027 is more consistent with C01 than C07, but it operates at departmental rather than individual-project level.
A8: C04 | B8: Efficient information exchange and tool interoperability | C8: Investable opportunity space | D8: Problems where information, files, models, or automation cannot move reliably or efficiently between tools, vendors, teams, or project contexts. | E8: 16 | F8: 15 | G8: 2 | H8: 16 | I8: WS1-P015 Inefficient file exchange between vendors | J8: WS1-P006 Inconsistent data setup across tools; WS1-P007 Inconsistent naming and data structures; WS1-P010 Weak change tracking in data-centric workflows; WS1-P014 Confusion from multiple project platforms; WS1-P016 Misaligned setups across software vendors | K8: WS1-P022 Automation difficult to understand and reuse | L8: PI-RTR-001 RTR Software Standardisation Exercise: Transport-wide exercise to map engineering software by service line/spearhead, identify overlaps, improve interoperability and establish an evidence-based basis for possible standardisation and rationalisation. PI-RTR-002 Unified Production Environment: Global initiative to align supported production platforms, interoperability, data governance, production knowledge and streamlined project environments, with AI and data-centric delivery as target outcomes. PI-RTR-003 Transforming Document Management: Global project to redesign document-management processes, implement a fit-for-purpose DMS and drive behavioural change and adoption across Ramboll projects. | M8: ESP-S013 Integrated multi-platform project environment (Norway); ESP-S014 BIMbot model exchange and automation layer (Norway) | N8: Potentially strong but currently narrow as a Primary cluster because only WS1-P015 has an unambiguous Primary fit. Its Secondary relationships show that interoperability is a meaningful ideation lens, but later evidence may support combining it with C03 or C02 rather than retaining it as a stand-alone focus area. | O8: Include where the central production loss is manual exchange, incompatible formats, inadequate exchange frequency, or inability to connect workflows across tools. | P8: Exclude inconsistent terminology or data definitions when exchange is technically possible but meaning is inconsistent. Exclude general platform proliferation where the main problem is unclear project setup rather than movement between systems. | Q8: The principal review question is whether C04 is a distinct opportunity space or a delivery mechanism within C02 and C03. Retain it separately for now because file exchange and integration can generate a different initiative conversation from standardising setups or data definitions.
A9: C05 | B9: Scalable automation and internally developed production tools (Citizen development) | C9: Investable opportunity space | D9: Problems preventing automation and internally developed tools from being created, quality-assured, shared, maintained, adapted, and scaled across projects or units. | E9: 78 | F9: 14.6 | G9: 2 | H9: 5 | I9: WS1-P001 Inconsistent use of AI and automation; WS1-P002 Barriers to scaling internally developed tools; WS1-P003 Uncoordinated citizen-developed AI tools; WS1-P021 No path from prototype to managed product; WS1-P022 Automation difficult to understand and reuse | J9: WS1-P020 Limited cross-country innovation sharing; WS1-P023 Underuse of modern modelling features | K9: S | L9: PI-RTR-004 Enabling Citizen Development: Ramboll Tech DD&P discovery and pilot initiative to determine business needs, tooling, enablement, governance and safe ways for colleagues to create lightweight automation and solutions. PI-RTR-005 Script Sharing Platform rollout and scaling: Scale a live, governed environment for sharing and reusing engineering automation assets including scripts, plugins and visual-programming solutions. PI-RTR-006 Software processes & portal: Ramboll Tech workstream improving software-portfolio governance, employee software journeys, request workflows and production-software support flows. | M9: ESP-S030 SPOT Workflow (Major Projects); ESP-S031 CODA Data Dictionary (CDD) (Major Projects) | N9: Strong ideation area. The Primary problems cover the progression from individual experimentation through quality control, publication, reuse, maintenance, and managed-product transition. This could generate materially different initiatives without limiting the discussion to AI or one product platform. | O9: Include where the main issue concerns the lifecycle, governance, reuse, quality, publication, integration, or scaling of automation and internally developed tools. | P9: Exclude broader user competence with vendor functionality. Exclude production-data foundations unless the record's primary issue is the data itself. | Q9: There is a risk of combining two related but different spaces: citizen-development governance and managed-product lifecycle. They are retained together because the evidence describes a continuous scaling problem, but later practice and initiative mapping should test whether they support separate conversations.
A10: C07 | B10: Client, regulatory and commercial conditions for digital production | C10: Hybrid, requiring review | D10: Problems where client restrictions, confidentiality, law, contractual arrangements, or commercial mechanisms constrain work sharing, AI use, resource deployment, or investment in digital production. | E10: 31 | F10: 14.5 | G10: 4 | H10: 20 | I10: WS1-P004 Confidentiality restricts work sharing with REC; WS1-P005 Client restrictions on AI and cross-border resources | J10: WS1-P008 Digital risks identified too late; WS1-P025 Current commercial model acts as blocker to digital resources and innovation | K10: None proposed | L10: N/A | M10: ESP-S007 Client-led data management and modelling instruction model (Finland); ESP-S024 Early-phase digital delivery manager involvement (UK&I); ESP-S025 Digital fit assessment (UK&I); ESP-S026 ISO 19650-aligned ProjectWise deployment model (UK&I) | N10: Mixed suitability. WS1-P004 and WS1-P005 contain genuine constraint conditions, but they may still support ideation around earlier identification, compliant delivery patterns, adaptation, or mitigation. C07 should not automatically be excluded from investment merely because the primary limiting conditions are external. | O10: Include where an external, contractual, regulatory, confidentiality, or commercial condition is the main cause of the production limitation. | P10: Exclude internal implementation, competence, governance, or organisational-alignment failures that Ramboll can act on directly. Do not assume that an external restriction makes the whole problem non-investable. | Q10: The cluster is now more internally coherent following the movement of WS1-P027 to C01. However, it remains narrow and primarily constraint-led. WS1-P025 belongs strongly in the commercial part of this cluster, but is Primary in C01 because its statement also concerns sufficient provision for digital delivery resources and investment in production improvement.
A11: C03 | B11: Structured, trustworthy and reusable production data | C11: Investable opportunity space | D11: Problems where inconsistent data definitions, naming, structures, change control, or performance information prevent reliable reuse, automation, monitoring, or decision-making. | E11: 54 | F11: 12.75 | G11: 11 | H11: 60 | I11: WS1-P006 Inconsistent data setup across tools; WS1-P007 Inconsistent naming and data structures; WS1-P009 Insufficient live project performance data; WS1-P010 Weak change tracking in data-centric workflows | J11: WS1-P015 Inefficient file exchange between vendors; WS1-P016 Misaligned setups across software vendors | K11: WS1-P001 Inconsistent use of AI and automation; WS1-P003 Uncoordinated citizen-developed AI tools | L11: PI-RTR-001 RTR Software Standardisation Exercise: Transport-wide exercise to map engineering software by service line/spearhead, identify overlaps, improve interoperability and establish an evidence-based basis for possible standardisation and rationalisation. PI-RTR-002 Unified Production Environment: Global initiative to align supported production platforms, interoperability, data governance, production knowledge and streamlined project environments, with AI and data-centric delivery as target outcomes. PI-RTR-003 Transforming Document Management: Global project to redesign document-management processes, implement a fit-for-purpose DMS and drive behavioural change and adoption across Ramboll projects. | M11: ESP-S005 CAD project manual and transport standards portal (Denmark); ESP-S007 Client-led data management and modelling instruction model (Finland); ESP-S014 BIMbot model exchange and automation layer (Norway); ESP-S015 Model Maturity Index (MMI) and property set standard (Norway); ESP-S018 Asset coding and IFC 4x3 delivery pattern (Norway); ESP-S020 Metadata and Naming + Managed Workspaces (Sweden); ESP-S026 ISO 19650-aligned ProjectWise deployment model (UK&I); ESP-S028 ProjectWise dashboards and Teams reporting (UK&I); ESP-S030 SPOT Workflow (Major Projects); ESP-S031 CODA Data Dictionary (CDD) (Major Projects); ESP-S032 BSDD testing / mapping (Major Projects) | N11: Strong ideation area because it brings together the foundations needed for data reuse, automation, reliable monitoring, and evidence-based tendering. Ideation should distinguish data semantics, data assurance, and operational performance insight rather than assuming one data platform would address all four. | O11: Include where the central production asset affected is structured data, including its semantics, consistency, traceability, or use as evidence. | P11: Exclude movement of files or models between platforms when the principal issue is exchange mechanics rather than data meaning or trust. Exclude general project standards unless they directly govern data structure or assurance. | Q11: WS1-P009 is more about management visibility than data standards and could become a separate production-insight area if later evidence shows sufficient depth. WS1-P006 overlaps C02 because "data setup" can refer both to project configuration and data structure.

Sheet Q3_Top problems
A1: Problems captured in Workshop 1, 14. August
J3: How relevant is the problem across units? | K3: Are there relevant existing local practices which can be part of the solution, and how relevant are they in total as judged to be across units?
P4: Relevance level
A5: Problem ID | B5: Clusters WS1_08-26 | C5: Primary Clusters WS2_08-26 | D5: Short title | E5: Problem statement | F5: Example or observation | G5: Value lens(es) | H5: Cross_Unit_ProblemRelevance_Count | I5: Pri signal, by voting (WS1, 8-26) | J5: Sum of unit problem relevance + vote (WS1, 8-26) | K5: Sum of unit relevance for the relevant local practices 06-26 | L5: Relevant ongoing initiatives 08-26 (AI inferred and QAd, 8-26) | M5: Relevant existing local standards and practices Q2-26 (AI inferred and QAd, 8-26) | N5: Type | O5: Top priority in | P5: NO | Q5: SE | R5: FI | S5: DK | T5: MP | U5: REC | V5: UK&I | W5: RelevantLocalPractices_Rationale (AI inferred and QAd, 8-26) | X5: Source File | Y5: Source Sheet | Z5: Record Origin | AA5: AIConfidence | AB5: ConfidenceReason | AC5: ReviewStatus | AD5: Reviewer | AE5: ReviewerComments | AF5: ReviewDecisionID | AG5: Source Type
A6: WS1-P017 | B6: Software standardization | C6: C02 Consistent and reusable project production environments | D6: Fragmented project setup and infrastructure | E6: Project teams and disciplines lack harmonised project setup and digital infrastructure when starting projects. Individuals push for different tools, standards, and ways of working, resulting in fragmented setups across projects, reduced work sharing, and an inability to harvest and reuse data from project to project. | F6: Each new project tends to reinvent its digital infrastructure and setup depending on who is involved. Even large projects across the same teams can have slightly different configurations, making cross-project reuse and standardisation difficult. | G6: Work sharing; Project write-downs | H6: 21 | I6: 2 | J6: =Problems[[#This Row],[Cross_Unit_ProblemRelevance_Count]]+Problems[[#This Row],[Pri signal, by voting (WS1, 8-26)]] -> 23 | K6: 81 | L6: PI-RTR-001 RTR Software Standardisation Exercise: Software harmonisation can reduce fragmented tool choices, but covers only part of the broader project-environment, standards, and ways-of-working problem. PI-RTR-002 Unified Production Environment: Streamlined project environments and aligned production platforms directly respond to fragmented project setup and digital infrastructure. PI-RTR-003 Transforming Document Management: A common document-management system and revised processes can standardise one important part of the project environment, but not the complete production setup. PI-RTR-007 Building our Project Management and Delivery department within Major Projects: Harmonised delivery capability can support more consistent project setup and management in major projects, but does not directly establish technical configurations or production infrastructure. | M6: ESP-S001 ProjectWise manager governance model (Denmark) ESP-S002 ProjectWise manager guide and standards portal (Denmark) ESP-S003 ProjectWise for production - RAMDK (Denmark) ESP-S004 Managed workspace in ProjectWise (Denmark) ESP-S005 CAD project manual and transport standards portal (Denmark) ESP-S008 Quadri / Trimble Connect project environment (Finland) ESP-S009 Finnish configuration packages for design tools (Finland) ESP-S010 Forma pilot with discipline templates (Finland) ESP-S013 Integrated multi-platform project environment (Norway) ESP-S019 CAD Configuration / Configuration Switch (Sweden) ESP-S020 Metadata and Naming + Managed Workspaces (Sweden) ESP-S022 Opt-in model via project support SharePoint page (Sweden) ESP-S024 Early-phase digital delivery manager involvement (UK&I) ESP-S025 Digital fit assessment (UK&I) ESP-S026 ISO 19650-aligned ProjectWise deployment model (UK&I) ESP-S027 ProjectWise build sheet and staged mobilisation checks (UK&I) | N6: Recurring | O6: MP | P6: Experienced | Q6: Experienced | R6: Experienced | S6: Experienced | T6: Experienced | U6: Experienced | V6: Experienced | W6: ESP-S001 Assigns named local responsibility for consistent project creation, access, and administration. ESP-S002 Documents the standard setup process and manager network used to establish project environments. ESP-S003 Provides repeatable project structures, permissions, external access, and project creation. ESP-S004 Delivers common tools, configurations, and templates whenever a project is opened. ESP-S005 Defines a common project-setup baseline for naming, coordinate systems, drawings, and discipline outputs. ESP-S008 Provides a structured project environment with repeatable folder, naming, and base-setup elements. ESP-S009 Gives users a packaged starting configuration for the design tools used in projects. ESP-S010 Pilots reusable discipline and client templates intended to make project creation more standardised. ESP-S013 Provides a connected multi-platform setup for complex project delivery. ESP-S019 Deploys standard CAD configurations and templates through one mechanism. ESP-S020 Standardises naming, metadata, and managed-workspace setup. ESP-S022 Gives projects a defined request route for obtaining a supported production environment. ESP-S024 Brings digital expertise into early project decisions so the project does not begin with an unsuitable setup. ESP-S025 Assesses project complexity and determines whether a managed environment and stronger digital support are required. ESP-S026 Provides a standard managed deployment with common folders, workflows, metadata, groups, and security. ESP-S027 Captures requirements, stages the environment, checks it, and approves it before production use. | X6: 2026-08 Workshop_1_problem_register.xlsx | Y6: Problem register | Z6: Imported | AC6: Not reviewed | AG6: Workshop 1 problem
A7: WS1-P026 | B7: Tool skills; Knowledge management; Commercial | C7: C06 Production knowledge, competence and adoption | D7: Delivery teams including REC lack correct skills to deliver digital outputs (models, drawings and data principally) right first time | E7: Currently project performance is impacted by the lack of skills within the business in the digital production space. This is causing a "silent drain" on projects as we're consistently spending more time and money on outputs than planned during tender without the ability to go back to clients to request additional fee due to being Ramboll error. This is impacting project performance on a large percentage of projects. | F7: Multiple projects/frequent issue. | G7: Project write-downs | H7: 21 | I7: 0 | J7: 21 | K7: 19 | L7: PI-RTR-002 Unified Production Environment: Supported platforms, production knowledge, and streamlined environments can strengthen technical delivery capability, but the initiative does not evidence competence development across all delivery teams or REC. PI-RTR-007 Building our Project Management and Delivery department within Major Projects: Explicitly builds geographically distributed project-management and delivery capability for more reliable delivery, directly addressing part of the capability gap, although not specifically competence in production tools. | M7: ESP-S006 Teams-based product information and support channel (Denmark) ESP-S011 Transport software standards portal and Teams communication channels (Finland) ESP-S012 Super-user network and office roadshow support model (Finland) ESP-S023 Project Hub (SharePoint coordination layer) (Sweden) | N7: Recurring | O7: UK&I | P7: Experienced | Q7: Experienced | R7: Experienced | S7: Experienced | T7: Experienced | U7: Experienced | V7: Experienced | W7: ESP-S006 Gives tool users access to updates, tips, known issues, and support guidance relevant to correct tool use. ESP-S011 Provides a shared source for software guidance, templates, installation instructions, and support services. ESP-S012 Provides local super-users who can explain standards, support users, and feed practical problems back to owners. ESP-S023 Supports onboarding and training in project procedures, folder structures, and production ways of working. | X7: 2026-08 Workshop_1_problem_register.xlsx | Y7: Problem register | Z7: Imported | AC7: Not reviewed | AG7: Workshop 1 problem
A8: WS1-P011 | B8: Knowledge management; Software standardization; Undocumented/unclear standards | C8: C02 Consistent and reusable project production environments | D8: Difficult cross-country project handover | E8: Sharing projects across teams, such as RFI to RNO or RNO to RDK, requires time to understand different processes, standards, software, and local practices. This can lead to rework or quality issues. | F8: An RUK team engineer working on an RFI project needed additional time to become familiar with Finland’s processes and software competencies. | G8: Work sharing | H8: 20 | I8: 2 | J8: =Problems[[#This Row],[Cross_Unit_ProblemRelevance_Count]]+Problems[[#This Row],[Pri signal, by voting (WS1, 8-26)]] -> 22 | K8: 61 | L8: PI-RTR-001 RTR Software Standardisation Exercise: Reducing variation in software portfolios and improving interoperability can remove one source of cross-country handover friction, although differences in local processes and practices remain outside its main scope. PI-RTR-002 Unified Production Environment: Shared production platforms, environments, and knowledge can make cross-country project handovers more consistent, although they do not fully resolve local working-practice differences. PI-RTR-007 Building our Project Management and Delivery department within Major Projects: Distributed project-management and delivery capability can support more reliable and harmonised delivery between geographies, particularly for large projects, but does not directly standardise software or local technical practices. | M8: ESP-S002 ProjectWise manager guide and standards portal (Denmark) ESP-S003 ProjectWise for production - RAMDK (Denmark) ESP-S004 Managed workspace in ProjectWise (Denmark) ESP-S005 CAD project manual and transport standards portal (Denmark) ESP-S008 Quadri / Trimble Connect project environment (Finland) ESP-S011 Transport software standards portal and Teams communication channels (Finland) ESP-S012 Super-user network and office roadshow support model (Finland) ESP-S013 Integrated multi-platform project environment (Norway) ESP-S017 Project SharePoint/Teams information hub (Norway) ESP-S023 Project Hub (SharePoint coordination layer) (Sweden) ESP-S026 ISO 19650-aligned ProjectWise deployment model (UK&I) | N8: Recurring | O8: REC | P8: Recognised | Q8: Experienced | R8: Experienced | S8: Experienced | T8: Experienced | U8: Experienced | V8: Experienced | W8: ESP-S002 Documents ProjectWise setup, support steps, and contacts, reducing dependence on informal local knowledge. ESP-S003 Gives project members a repeatable structure and controlled access when joining or transferring between projects. ESP-S004 Makes the same project tools, configurations, templates, and support files available to colleagues in different locations. ESP-S005 Gives incoming teams a common reference for project setup, naming, drawing production, and discipline standards. ESP-S008 Provides a shared project environment and standard base structure that supports teams working in the same project context. ESP-S011 Gives transferred staff one source for current software guidance, templates, installation information, and support. ESP-S012 Provides local people who can explain standards and route questions and feedback to responsible owners. ESP-S013 Connects the platforms used by internal and external teams and uses digital resources to bridge differences between systems. ESP-S017 Gives project members a visible entry point to the project's systems, guidance, links, and updates. ESP-S023 Provides a repeatable project-information and onboarding hub covering procedures, folder structures, and navigation. ESP-S026 Gives users and partners a familiar controlled environment through common structures, workflows, metadata, and permissions. | X8: 2026-08 Workshop_1_problem_register.xlsx | Y8: Problem register | Z8: Imported | AC8: Not reviewed | AG8: Workshop 1 problem
A9: WS1-P012 | B9: Knowledge management; Software standardization; Undocumented/unclear standards | C9: C02 Consistent and reusable project production environments | D9: Local standards hinder work sharing | E9: Work sharing between business units is difficult because units have their own poorly documented project standards. There is resistance to moving even a service line-coordinated project standard forward. | F9: At the Tampere office it was asked: ‘How can we access the data that is located in the Lahti office network drive?’ Street and landscaping have the highest resistance to change. | G9: Work sharing; Project write-downs; Tender competitiveness | H9: 20 | I9: 0 | J9: =Problems[[#This Row],[Cross_Unit_ProblemRelevance_Count]]+Problems[[#This Row],[Pri signal, by voting (WS1, 8-26)]] -> 20 | K9: 68 | L9: PI-RTR-001 RTR Software Standardisation Exercise: Supports cross-geography software harmonisation, but does not directly document or implement common project standards across business units. PI-RTR-002 Unified Production Environment: Common production knowledge and aligned environments can provide a basis for shared standards, although local resistance and incomplete documentation require additional adoption measures. PI-RTR-007 Building our Project Management and Delivery department within Major Projects: Its harmonised delivery focus and Major Projects Handbook can support more consistent delivery practices, but only partly address local technical standards and resistance to common ways of working. | M9: ESP-S002 ProjectWise manager guide and standards portal (Denmark) ESP-S003 ProjectWise for production - RAMDK (Denmark) ESP-S004 Managed workspace in ProjectWise (Denmark) ESP-S005 CAD project manual and transport standards portal (Denmark) ESP-S007 Client-led data management and modelling instruction model (Finland) ESP-S008 Quadri / Trimble Connect project environment (Finland) ESP-S011 Transport software standards portal and Teams communication channels (Finland) ESP-S012 Super-user network and office roadshow support model (Finland) ESP-S019 CAD Configuration / Configuration Switch (Sweden) ESP-S020 Metadata and Naming + Managed Workspaces (Sweden) ESP-S023 Project Hub (SharePoint coordination layer) (Sweden) ESP-S026 ISO 19650-aligned ProjectWise deployment model (UK&I) | N9: Recurring | O9: FI | P9: Recognised | Q9: Experienced | R9: Experienced | S9: Experienced | T9: Experienced | U9: Experienced | V9: Experienced | W9: ESP-S002 Makes setup guidance and responsible contacts explicit rather than leaving standards as informal local knowledge. ESP-S003 Implements a repeatable project structure and permission model across relevant projects. ESP-S004 Delivers common configurations and templates through the project environment rather than through local copies. ESP-S005 Documents common CAD and project standards in one reference point and allows projects to document only justified exceptions. ESP-S007 Translates client and agency standards into a defined project baseline for data and modelling. ESP-S008 Provides standard folder, naming, and base-setup elements within a shared project environment. ESP-S011 Provides a trusted location for current standards, templates, instructions, and support information. ESP-S012 Reinforces standards through local support, communication, feedback, and office outreach. ESP-S019 Deploys official CAD configurations and templates through a common configuration mechanism. ESP-S020 Standardises metadata, naming, and managed-workspace setup within ProjectWise. ESP-S023 Presents procedures and company practices through a repeatable project-hub structure. ESP-S026 Implements common CDE structures, metadata, workflows, and controls for participating organisations. | X9: 2026-08 Workshop_1_problem_register.xlsx | Y9: Problem register | Z9: Imported | AC9: Not reviewed | AG9: Workshop 1 problem
A10: WS1-P001 | B10: Citizen development | C10: C05 Scalable automation and internally developed production tools | D10: Inconsistent use of Enable AI and automation | E10: AI and automatization is used non-systematically among different disciplines and depends on individuals. AI tools are used by individuals and some specialist communities, but there is no common way to quality assure, share, or scale working methods. The level of maturity also varies between disciplines. | F10: Not provided. | G10: Enable AI and automation | H10: 19 | I10: 1 | J10: =Problems[[#This Row],[Cross_Unit_ProblemRelevance_Count]]+Problems[[#This Row],[Pri signal, by voting (WS1, 8-26)]] -> 20 | K10: 0 | L10: PI-RTR-004 Enabling Citizen Development: Addresses inconsistent Enable AI and automation practices by establishing common tooling, enablement, governance, and safe approaches for citizen development. PI-RTR-005 Script Sharing Platform rollout and scaling: Provides a governed environment for sharing and reusing automation assets, addressing the lack of systematic sharing and scaling, although not the full competence and quality-assurance problem. | M10: N/A | N10: Emerging | O10: NO | P10: Recognised | Q10: Experienced | R10: Experienced | S10: Experienced | T10: Experienced | U10: Recognised | V10: Experienced | W10: N/A | X10: 2026-08 Workshop_1_problem_register.xlsx | Y10: Problem register | Z10: Imported | AC10: Not reviewed | AG10: Workshop 1 problem
A11: WS1-P013 | B11: Knowledge management; Undocumented/unclear standards | C11: C06 Production knowledge, competence and adoption | D11: Scattered guidance and support information | E11: Information about ways of working, software support, education, etc. is scattered and unstructured. This makes it difficult to onboard new staff and establish standardised ways of working. | F11: Onboarding new staff is a struggle. There is no single point of entry for information. | G11: Project write-downs | H11: 19 | I11: 2 | J11: =Problems[[#This Row],[Cross_Unit_ProblemRelevance_Count]]+Problems[[#This Row],[Pri signal, by voting (WS1, 8-26)]] -> 21 | K11: 35 | L11: PI-RTR-002 Unified Production Environment: Production knowledge is part of its scope and could make guidance more consistent, although a single entry point for all support, education, and onboarding information is not explicitly evidenced. PI-RTR-003 Transforming Document Management: A fit-for-purpose document-management system and revised processes can improve the organisation of document-management guidance, but not all software, education, and working-method information. PI-RTR-006 Software processes & portal: Directly addresses employee software journeys, software requests, and production-software support flows, responding to scattered software guidance and support information. | M11: ESP-S002 ProjectWise manager guide and standards portal (Denmark) ESP-S005 CAD project manual and transport standards portal (Denmark) ESP-S006 Teams-based product information and support channel (Denmark) ESP-S011 Transport software standards portal and Teams communication channels (Finland) ESP-S012 Super-user network and office roadshow support model (Finland) ESP-S017 Project SharePoint/Teams information hub (Norway) ESP-S023 Project Hub (SharePoint coordination layer) (Sweden) | N11: Recurring | O11: SE | P11: Recognised | Q11: Experienced | R11: Experienced | S11: Experienced | T11: Experienced | U11: Recognised | V11: Experienced | W11: ESP-S002 Combines setup instructions, manager contacts, and support guidance in a common portal. ESP-S005 Provides one reference point for CAD and project setup standards. ESP-S006 Provides a visible channel for tool updates, support information, release information, and tips. ESP-S011 Provides one software-information site supported by Teams communication channels. ESP-S012 Complements written guidance with local super-users who can explain it and route feedback. ESP-S017 Gathers project links, guidance, updates, and tool information into one project entry point. ESP-S023 Gathers project procedures, navigation, communication, and onboarding information in a reusable hub. | X11: 2026-08 Workshop_1_problem_register.xlsx | Y11: Problem register | Z11: Imported | AC11: Not reviewed | AG11: Workshop 1 problem
A12: WS1-P008 | B12: Digital Delivery Management | C12: C01 Reliable project mobilisation and digital delivery governance | D12: Digital risks identified too late | E12: Digital requirements and risks are not sufficiently identified in the tender phase. There is often insufficient time to identify all risks related to digital requirements, and this is moved to the post-contract phase, resulting in underestimated work or competence needed to fulfil client requirements. This often affects project performance. | F12: Not provided. | G12: Project write-downs | H12: 18 | I12: 1 | J12: =Problems[[#This Row],[Cross_Unit_ProblemRelevance_Count]]+Problems[[#This Row],[Pri signal, by voting (WS1, 8-26)]] -> 19 | K12: 7 | L12: N/A | M12: ESP-S024 Early-phase digital delivery manager involvement (UK&I) ESP-S025 Digital fit assessment (UK&I) | N12: Recurring | O12: NO | P12: Experienced | Q12: Experienced | R12: Experienced | S12: Experienced | T12: Experienced | U12: No known relevance | V12: Experienced | W12: ESP-S024 Involves a Digital Delivery Manager during the tender gates to review digital requirements, risks, standards, and setup decisions before mobilisation. ESP-S025 Provides a structured early assessment of complexity, digital requirements, standards gaps, and delivery risks. | X12: 2026-08 Workshop_1_problem_register.xlsx | Y12: Problem register | Z12: Imported | AC12: Not reviewed | AG12: Workshop 1 problem
A13: WS1-P027 | B13: Commercial | C13: C01 Reliable project mobilisation and digital delivery governance | D13: Consistency across departments in terms of digital plan and focus, lack of HoD KPI's supporting improvements in the digital space | E13: Improving the situation in the digital management and delivery space requires all departments to push in the same direction. Historically there has been a disconnect between departments which has impacted ability to improve the situation. Moving forward there is a need for all HoD's to be involved in and understand digital needs of the business and have clear goals/KPI's associated with this. | F13: Department Plans | G13: Work sharing; Enable AI and automation; Project write-downs; Tender competitiveness | H13: 17 | I13: 0 | J13: 17 | K13: 0 | L13: PI-RTR-007 Building our Project Management and Delivery department within Major Projects: Its department-building, geographic expansion, delivery focus, and Major Projects Handbook can provide stronger common direction within Major Projects, but do not evidence aligned priorities and performance measures across all Transport departments. | M13: N/A | N13: Recurring | O13: UK&I | P13: Recognised | Q13: Experienced | R13: Recognised | S13: Experienced | T13: Recognised | U13: Recognised | V13: Experienced | W13: N/A | X13: 2026-08 Workshop_1_problem_register.xlsx | Y13: Problem register | Z13: Imported | AC13: Not reviewed | AG13: Workshop 1 problem
A14: WS1-P018 | B14: Software standardization | C14: C02 Consistent and reusable project production environments | D14: Project standards not fully implemented | E14: The project model, folder structure, and other standards are not fully implemented, resulting in diverse ways of working. | F14: Different ways of working mean longer start-up, rework, reinventing the wheel, and poorer quality. | G14: Work sharing; Enable AI and automation; Project write-downs; Tender competitiveness | H14: 17 | I14: 1 | J14: =Problems[[#This Row],[Cross_Unit_ProblemRelevance_Count]]+Problems[[#This Row],[Pri signal, by voting (WS1, 8-26)]] -> 18 | K14: 70 | L14: PI-RTR-001 RTR Software Standardisation Exercise: Can support consistent software choices, but does not directly implement project models, folder structures, templates, or standards. PI-RTR-002 Unified Production Environment: Alignment of production processes, knowledge, platforms, and environments supports practical implementation of consistent project standards and ways of working. PI-RTR-003 Transforming Document Management: Process revision, system implementation, and behavioural adoption directly support implementation of document-management standards, although not all project-production standards. PI-RTR-007 Building our Project Management and Delivery department within Major Projects: The harmonised delivery focus and Major Projects Handbook can support implementation of common delivery practices, but the documented scope does not specifically cover digital models or folder standards. | M14: ESP-S001 ProjectWise manager governance model (Denmark) ESP-S003 ProjectWise for production - RAMDK (Denmark) ESP-S004 Managed workspace in ProjectWise (Denmark) ESP-S005 CAD project manual and transport standards portal (Denmark) ESP-S008 Quadri / Trimble Connect project environment (Finland) ESP-S009 Finnish configuration packages for design tools (Finland) ESP-S010 Forma pilot with discipline templates (Finland) ESP-S011 Transport software standards portal and Teams communication channels (Finland) ESP-S012 Super-user network and office roadshow support model (Finland) ESP-S019 CAD Configuration / Configuration Switch (Sweden) ESP-S020 Metadata and Naming + Managed Workspaces (Sweden) ESP-S023 Project Hub (SharePoint coordination layer) (Sweden) ESP-S026 ISO 19650-aligned ProjectWise deployment model (UK&I) ESP-S027 ProjectWise build sheet and staged mobilisation checks (UK&I) | N14: Recurring | O14: SE | P14: Experienced | Q14: Experienced | R14: Recognised | S14: needs checking | T14: Experienced | U14: Recognised | V14: Experienced | W14: ESP-S001 Uses named managers to create projects and keep structures and access aligned with the shared standard. ESP-S003 Implements standard project structures and permission groups directly in the production environment. ESP-S004 Delivers required configurations, templates, and support files through the managed workspace. ESP-S005 Provides the documented standards projects are expected to follow and a method for recording exceptions. ESP-S008 Implements repeatable folder, naming, and base-setup elements in the project environment. ESP-S009 Deploys available templates and configurations within the design-tool setup. ESP-S010 Uses prepared discipline templates to make new project creation more consistent. ESP-S011 Makes current standards and templates discoverable and communicates updates to users. ESP-S012 Supports practical adoption through local super-users, feedback, and outreach. ESP-S019 Gives projects access to official CAD configurations and templates through a common switch. ESP-S020 Implements metadata, naming, and workspace rules in ProjectWise. ESP-S023 Presents project procedures and company practices through a repeatable project-hub template. ESP-S026 Implements standard structures, workflows, metadata, security, and review controls in the CDE. ESP-S027 Checks workflows, numbering, and environments before the production setup is approved. | X14: 2026-08 Workshop_1_problem_register.xlsx | Y14: Problem register | Z14: Imported | AC14: Not reviewed | AG14: Workshop 1 problem
A15: WS1-P020 | B15: Tool sharing | C15: C06 Production knowledge, competence and adoption | D15: Limited cross-country innovation sharing | E15: Experience sharing across countries is poor for innovative solutions that could strengthen important tenders. There are few dedicated arenas for sharing innovative solutions or ways of working across countries. | F15: Not provided. | G15: Tender competitiveness | H15: 17 | I15: 5 | J15: =Problems[[#This Row],[Cross_Unit_ProblemRelevance_Count]]+Problems[[#This Row],[Pri signal, by voting (WS1, 8-26)]] -> 22 | K15: 0 | L15: PI-RTR-002 Unified Production Environment: Shared production knowledge can improve cross-country exchange of methods and solutions, although dedicated innovation-sharing arenas and tender application are not explicit. PI-RTR-005 Script Sharing Platform rollout and scaling: Makes reusable engineering automation assets visible across teams and geographies, directly improving sharing of one important category of production innovation, although it does not cover all types of innovation or tender collaboration. | M15: N/A | N15: Recurring | O15: NO | P15: Recognised | Q15: Recognised | R15: Recognised | S15: Experienced | T15: Experienced | U15: Recognised | V15: Experienced | W15: N/A | X15: 2026-08 Workshop_1_problem_register.xlsx | Y15: Problem register | Z15: Imported | AC15: Not reviewed | AG15: Workshop 1 problem
A16: WS1-P004 | B16: Data security | C16: C07 Client, regulatory and commercial conditions for digital production | D16: Confidentiality restricts work sharing with REC | E16: Confidentiality requirements make it difficult to share work with REC. Framework agreements can restrict consultants from using REC for some projects because of the risk of data breaches. | F16: Not provided. | G16: Work sharing | H16: 17 | I16: 2 | J16: =Problems[[#This Row],[Cross_Unit_ProblemRelevance_Count]]+Problems[[#This Row],[Pri signal, by voting (WS1, 8-26)]] -> 19 | K16: 0 | L16: N/A | M16: N/A | N16: Emerging | O16: REC | P16: Recognised | Q16: Recognised | R16: Experienced | S16: needs checking | T16: Experienced | U16: Experienced | V16: Experienced | W16: N/A | X16: 2026-08 Workshop_1_problem_register.xlsx | Y16: Problem register | Z16: Imported | AC16: Not reviewed | AG16: Workshop 1 problem
